<mujoco model="parallel_5_bar_mechanism">
    <compiler angle="degree" inertiafromgeom="true"/>
    <option gravity="0 0 -9.81" integrator="RK4" timestep="0.01"/>
    <asset>
        <texture name="grid" type="2d" builtin="checker" rgb1=".1 .2 .3" rgb2=".2 .3 .4" width="300" height="300"/>
        <material name="grid" texture="grid" texrepeat="8 8" reflectance=".2"/>
     </asset>

    <worldbody>
        <light name="top" pos="0 0 1"/>
        <geom name="worldbody" size="1 1 .01" pos="0 0 -.2" type="plane" material="grid"/>
        <body name="base" pos="0 0 0">
            <geom name="base" type="box" size="0.075 0.02540 0.0508" pos="0 0 0" rgba="0.5 0.5 0.5 1"/>
            <body name="proximal1" pos="-0.075 0 0.07620" euler="0 0 135">
                <joint name="joint1" type="hinge" axis="0 0 1" pos="0 0 0"   damping="0" stiffness="0" ref="135"/>
                <geom name="proximal1" type="box" size="0.1 0.02540 0.02540" pos="0.1 0 0" rgba="1 0 0 1"/>
                <body name="distal1" pos="0.2 0 -0.0508" euler="0 0 -77.755376534">
                    <joint name="joint3" type="hinge" axis="0 0 1" pos="0 0 0"  damping="0" stiffness="0" ref="57.244623466"/>
                    <geom name="distal1" type="box" size="0.2 0.02540 0.02540" pos="0.2 0 0" rgba="0 1 0 1"/>
                    <body name="end_effector" pos="0.4 0 -0.02540">
					    <geom contype="0" name="end_effector" pos="0 0 0" rgba="0.0 0.8 0.6 1" size=".01" type="sphere"/>
				    </body>
                </body>
            </body>
            <body name="proximal2" pos="0.075 0 -0.07620" euler="0 0 -135">
                <joint name="joint2" type="hinge" axis="0 0 1" pos="0 0 0"  damping="0" stiffness="0"  ref="-135"/>
                <geom name="proximal2" type="box" size="0.1 0.02540 0.02540" pos="-0.1 0 0" rgba="1 0 0 1"/>
                <body name="distal2" pos="-0.2 0 0.0508" euler="0 0 77.755376534">
                    <joint name="joint4" type="hinge" axis="0 0 1" pos="0 0 0"  damping="0" stiffness="0" ref="-57.244623466"/>
                    <geom name="distal2" type="box" size="0.2 0.02540 0.02540" pos="-0.2 0 0" rgba="0 1 0 1"/>
                </body>
            </body>
        </body>
        <body name="target" pos=".25 .250 0">
			<joint armature="0" axis="1 0 0" damping="0" limited="true" name="target_x" pos="0 0 0" range="-1 1" ref=".25" stiffness="0" type="slide"/>
			<joint armature="0" axis="0 1 0" damping="0" limited="true" name="target_y" pos="0 0 0" range="-1 1" ref=".25" stiffness="0" type="slide"/>
			<geom conaffinity="0" contype="0" name="target" pos="0 0 0" rgba="0.9 0.2 0.2 1" size="0.01" type="sphere"/>
	    </body>
    </worldbody>
    <equality>
		<connect anchor="0.4 0 0" body1="distal1" body2="distal2" name="equality_constraint"/>
	</equality>
    <sensor>
		<framepos objtype="body" objname="end_effector"/>
		<framelinvel objtype="body" objname="end_effector"/>
	</sensor>
    <actuator>
        <motor joint="joint1" ctrllimited="true"  ctrlrange="-10.0 10.0"/>
        <motor joint="joint2" ctrllimited="true"  ctrlrange="-10.0 10.0"/>
    </actuator>
</mujoco>
