
<mujoco model="parallel_5_bar_mechanism">
    <compiler angle="degree" inertiafromgeom="true"/>
    <option gravity="0 0 -9.81" integrator="RK4" timestep="0.01"/>
    <asset>
        <texture name="grid" type="2d" builtin="checker" rgb1=".1 .2 .3" rgb2=".2 .3 .4" width="300" height="300"/>
        <material name="grid" texture="grid" texrepeat="8 8" reflectance=".2"/>
     </asset>

    <worldbody>
        <light name="top" pos="0 0 1"/>
        <geom name="worldbody" size="1 1 .01" pos="0 0 -.2" type="plane" material="grid"/>
        <body name="base" pos="0 0 0">
            <body name="proximal1" pos="-0.0375 0.0 0.04200000000000001" euler="0 0 135.0">
                <joint name="joint1" type="hinge" axis="0 0 1" pos="0 0 0"   damping="0" stiffness="0" ref="135.0"/>
                <geom name="proximal1" type="box" size="0.05 0.01 0.0125" pos="0.05 0 0" rgba="1 0 0 1" density="2700"/>
                <body name="distal1" pos="0.1 0 -0.028" euler="0 0 -77.755376534">
                    <joint name="joint3" type="hinge" axis="0 0 1" pos="0 0 0"  damping="0" stiffness="0" ref="-77.755376534"/>
                    <geom name="distal1" type="box" size="0.1 0.01 0.0125" pos="0.1 0 0" rgba="0 1 0 1" density="2700"/>
                    <body name="end_effector" pos="0.2 0 0">
					    <geom contype="0" name="end_effector" pos="0 0 0" rgba="0.0 0.8 0.6 1" size=".01" type="sphere"/>
				    </body>
                </body>
            </body>
            <body name="proximal2" pos="0.0375 0.0 -0.04200000000000001" euler="0 0 -135.0">
                <joint name="joint2" type="hinge" axis="0 0 1" pos="0 0 0"  damping="0" stiffness="0"  ref="-135.0"/>
                <geom name="proximal2" type="box" size="0.05 0.01 0.0125" pos="-0.05 0 0" rgba="1 0 0 1" density="2700"/>
                <body name="distal2" pos="-0.1 0 0.028" euler="0 0 77.755376534">
                    <joint name="joint4" type="hinge" axis="0 0 1" pos="0 0 0"  damping="0" stiffness="0" ref="77.755376534"/>
                    <geom name="distal2" type="box" size="0.1 0.01 0.0125" pos="-0.1 0 0" rgba="0 1 0 1" density="2700"/>
                </body>
            </body>
        </body>
        <body name="target" pos=".125 .125 0">
			<joint armature="0" axis="1 0 0" damping="0" limited="true" name="target_x" pos="0 0 0" range="-1 1" ref=".125" stiffness="0" type="slide"/>
			<joint armature="0" axis="0 1 0" damping="0" limited="true" name="target_y" pos="0 0 0" range="-1 1" ref=".125" stiffness="0" type="slide"/>
			<geom conaffinity="0" contype="0" name="target" pos="0 0 0" rgba="0.9 0.2 0.2 1" size="0.01" type="sphere"/>
	    </body>
    </worldbody>
    <equality>
		<connect anchor="0.2 0 0" body1="distal1" body2="distal2" name="equality_constraint"/>
	</equality>
    <sensor>
		<framepos objtype="body" objname="end_effector"/>
		<framelinvel objtype="body" objname="end_effector"/>
	</sensor>
    <actuator>
        <!position joint="joint1" ctrllimited="true"  ctrlrange="0 3.14" kp="3" kv="0.1"/>
        <!position joint="joint2" ctrllimited="true"  ctrlrange="-3.14 0" kp="3" kv="0.1"/>
        <motor joint="joint1" ctrllimited="true"  ctrlrange="-1.6 1.6"/>
        <motor joint="joint2" ctrllimited="true"  ctrlrange="-1.6 1.6"/>
    </actuator>
</mujoco>
